Workbook

Sheet Instructions
A1: Instructions
A5: Hello everyone and thank for choosing this program to keep track of your perfect file items in Final Fantasy IX! ;) First off, I want to congratulate you on
A6: completing Atomos199's Excalibur II Perfect Game challenge (if you have). Second, I hope that this program will be helpful and useful to you and your friends
A7: who also have completed this challenge. And third, it is an honor to help everyone who really wants to do this on the first try and not screw up and backtrack
A8: so much. If anyone has ways to make this better, PLEASE let me know. The best way of contacting me would be GameFAQS. My username is IllusionGamer90,
A9: so you can send me a private message and let me know of anything to make this better. And now, here are the instructions:
A11: 1. Click on the "Perfect Amounts" sheet below right next to the "Instructions" sheet. This will take you to every item in the game in their Auto position.
A12: What you will need to do is save first. Then, unequip every member and equip their weapon with something you have more than one of, like their missable
A13: weapons bought during the run. Then, you will need to Auto your inventory by opening the menu, going to Item, press O, go to Arrange, then finally Auto.
A15: 2. The items in the "Perfect Amounts" are in their Auto order, which is why I asked you to Auto your items. Click on the box "Your Desired Amount"
A16: on Potions and type in the amount you would like in your final inventory. Then Press Enter for the next item and so on. By default, the perfect amount is
A17: already typed in for you, but you can change this number if desired. After that is done, go through all of your items and type in the amount of the item in
... A43: 6. And for all those geeks out there, I have included a "Math Behind This" Sheet to show you how all this came along.

Sheet Perfect Amounts
A1: Item | B1: Cost | C1: Sell | D1: Your Desired Amount | E1: Specified Amount In File | F1: Amount for 'Perfect Amount'
A2: Potion | B2: 50 | C2: 25 | D2: 99 | E2: 0 | F2: 99
A3: Hi-Potion | B3: 200 | C3: 100 | D3: 99 | E3: 0 | F3: 99
A4: Ether | B4: 500 | C4: 1000 | D4: 99 | E4: 0 | F4: 99
A5: Elixir | B5: - | C5: 1 | D5: 99 | E5: 0 | F5: 99
A6: Phoenix Down | B6: 150 | C6: =B6/2 -> 75 | D6: 99 | E6: 0 | F6: 99
A7: Remedy | B7: 300 | C7: =B7/2 -> 150 | D7: 99 | E7: 0 | F7: 99
A8: Antidote | B8: 50 | C8: =B8/2 -> 25 | D8: 99 | E8: 0 | F8: 99
A9: Eye Drops | B9: 50 | C9: =B9/2 -> 25 | D9: 99 | E9: 0 | F9: 99
A10: Echo Screen | B10: 50 | C10: =B10/2 -> 25 | D10: 99 | E10: 0 | F10: 99
A11: Soft | B11: 100 | C11: =B11/2 -> 50 | D11: 99 | E11: 0 | F11: 99
A12: Magic Tag | B12: 100 | C12: =B12/2 -> 50 | D12: 99 | E12: 0 | F12: 99
A13: Annoyntment | B13: 150 | C13: =B13/2 -> 75 | D13: 99 | E13: 0 | F13: 99
A14: Vaccine | B14: 100 | C14: =B14/2 -> 50 | D14: 99 | E14: 0 | F14: 99
A15: Gysahl Greens | B15: 80 | C15: 30 | D15: 99 | E15: 0 | F15: 99
A16: Phoenix Pinion | B16: 300 | C16: 1000 | D16: 99 | E16: 0 | F16: 99
A17: Dead Pepper | B17: - | C17: 50 | D17: 99 | E17: 0 | F17: 99
A18: Tent | B18: 800 | C18: 400 | D18: 99 | E18: 0 | F18: 99
A19: Dark Matter | B19: - | C19: 1 | D19: 3 | E19: 0 | F19: 3 | G19: Missable
A20: Pinwheel | B20: 200 | C20: 100 | D20: 99 | E20: 0 | F20: 99
A21: Rising Sun | B21: 500 | C21: 250 | D21: 99 | E21: 0 | F21: 99
A22: Wing Edge | B22: - | C22: 1500 | D22: 99 | E22: 0 | F22: 99
A23: Hammer | B23: - | C23: 125 | D23: 1 | E23: 0 | F23: 1
A24: Dagger | B24: 320 | C24: 160 | D24: 2 | E24: 0 | F24: 2
A25: Mage Masher | B25: 500 | C25: 250 | D25: 2 | E25: 0 | F25: 2
A26: Mythril Dagger | B26: 950 | C26: =B26/2 -> 475 | D26: 2 | E26: 0 | F26: 2
A27: Gladius | B27: 2300 | C27: =B27/2 -> 1150 | D27: 2 | E27: 0 | F27: 2
A28: Zorlin Shape | B28: 6000 | C28: =B28/2 -> 3000 | D28: 2 | E28: 0 | F28: 2 | G28: Missable
A29: Orichalcon | B29: 17000 | C29: =B29/2 -> 8500 | D29: 2 | E29: 0 | F29: 2
A30: Butterfly Sword | B30: 300 | C30: 650 | D30: 2 | E30: 0 | F30: 2
A31: The Ogre | B31: 700 | C31: 850 | D31: 2 | E31: 0 | F31: 2
A32: Exploda | B32: 1000 | C32: 1400 | D32: 2 | E32: 0 | F32: 2
A33: Rune Tooth | B33: 2000 | C33: 1900 | D33: 2 | E33: 0 | F33: 2
A34: Angel Bless | B34: 9000 | C34: 3500 | D34: 2 | E34: 0 | F34: 2
A35: Sargatanas | B35: 12000 | C35: 4750 | D35: 2 | E35: 0 | F35: 2
A36: Masamune | B36: 16000 | C36: 6500 | D36: 2 | E36: 0 | F36: 2
A37: The Tower | B37: - | C37: 15000 | D37: 1 | E37: 0 | F37: 1
A38: Ultima Weapon | B38: - | C38: 20000 | D38: 1 | E38: 0 | F38: 1
A39: Broadsword | B39: 330 | C39: =B39/2 -> 165 | D39: 2 | E39: 0 | F39: 2
A40: Iron Sword | B40: 660 | C40: =B40/2 -> 330 | D40: 2 | E40: 0 | F40: 2
...

Sheet Future Treasures
A1: Item | B1: Location(s) | C1: Amount Gettting
A2: Ether | B2: Alexandria, Quan's Dwelling x2, Treno, | C2: 0
B3: Bird's Eye Lagoon x3, Forgotten Lagoon x5,
B4: Abandoned Lagoon x4, Forbidden Forest x7, | D4: *can also steal and win from various enemies*
B5: Dive Spot north of Conde Petie x9,
B6: Forgotten Plains x5
A8: Elixir | B8: Alexandria, Lindblum, Daguerreo x2, | C8: 0
B9: Steal from Ozma, Steal from Quale, | D9: *steal the rest from Yans*
B10: Steal from Deathguise, Forbidden Forest x2,
B11: Dive Spot north of Conde Petie x7, Stellazzio prize
A13: Remedy | B13: Alexandria | C13: 0
A15: Phoenix Pinion | B15: Randon Kupo Nut prize (up to 4), Stellazzio prize, | C15: 0 | D15: *can also steal and win from various enemies*
B16: Burmecia, Abandoned Beach x9, Sea at Dusk x15,
A18: Dark Matter | B18: Buy in Treno Auction, Steal from Ozma, | C18: 0 | D18: *disregard auction if gotten during run*
B19: Dropped from Ozma
A21: Wing Edge | B21: Uncultivated Land x3, Forbidden Forest x10, Trade | C21: 0 | D21: *Steal the rest from Crystal Tiamat (16/256) & (1/256)*
B22: 3500 H&C points
A24: Hammer | B24: Stellazzio prize | C24: 0
A26: Dagger | B26: Ipsen's Castle | C26: 0
A28: Ultima Weapon | B28: Dive Spot where Shimmering Island was | C28: 0
A30: Broadsword | B30: Ipsen's Castle | C30: 0
A32: Blood Sword | B32: Stellazzio prize | C32: 0
A34: Excalibur | B34: Daguerreo | C34: 0
A36: Ragnarok | B36: Outer Island 2 | C36: 0 | D36: *disregard if gotten during run*
A38: Javelin | B38: Ipsen's Castle | C38: 0
A40: Kain's Lance | B40: Memoria | C40: 0
A42: Dragon's Hair | B42: Mountain Crack northwest of Oeilvert | C42: 0
A44: Cat's Claws | B44: ipsen's Castle | C44: 0
A46: Dragon's Claws | B46: Forgotten Lagoon | C46: 0
A48: Kaiser Knuckles | B48: Dusk Plains | C48: 0 | D48: *disregard if gotten during run*
A50: Duel Claws | B50: Steal from Deathguise | C50: 0
A52: Rune Claws | B52: Memoria | C52: 0
A54: Air Racket | B54: Ipsen's Castle | C54: 0
A56: Tiger Racket | B56: Dive Spot below Quan's Dwelling | C56: 0
A58: Whale Whisker | B58: Ocean | C58: 0 | D58: *disregard if gotten during run*
A60: Golem's Flute | B60: Ipsen's Castle | C60: 0
A62: Angel's Flute | B62: Memoria | C62: 0
A64: Mage Staff | B64: Ipsen's Castle | C64: 0
A66: High Mage Staff | B66: Forbidden Forest | C66: 0
A68: Mace of Zeus | B68: Memoria | C68: 0
...

Sheet Buying and Synthing
A1: Buy | H1: Amount of Gil needed: | K1: =SUM(B11,B48,B69,B90,B122,B134,B163,B169,B181,B192,B217,B224,B233) -> 5247920 | L1: Gil
H2: *Be sure to sell necessary stuff before working on the Gil needed*
A3: Burmecia | H3: **Have the following before starting:** | L3: Get | N3: Amount Gotten
A4: Buy | B4: Item | C4: Cost | D4: Sell | E4: Total | F4: Amount Purchased | L4: =IF('Perfect Amounts'!D235+'Perfect Amounts'!D236+'Perfect Amounts'!D234+'Perfect Amounts'!D220+'Perfect Amounts'!D226-'Perfect Amounts'!E11<0,0,'Perfect Amounts'!D235+'Perfect Amounts'!D236+'Perfect Amounts'!D234+'Perfect Amounts'!D220+'Perfect Amounts'!D226-'Perfect Amounts'!E11-N4) -> 36 | M4: Soft
A5: ='Perfect Amounts'!D136-'Perfect Amounts'!E136+'Perfect Amounts'!D189-'Perfect Amounts'!E189-'Future Treasures'!C117+'Perfect Amounts'!D192-'Perfect Amounts'!E192-'Future Treasures'!C123+'Perfect Amounts'!D233-'Perfect Amounts'!E233-'Buying and Synthing'!F5 -> 22 | B5: Steepled Hat | C5: 260 | D5: =C5/2 -> 130 | E5: =IF(A5>0,C5*A5,D5*A5) -> 5720 | L5: =IF('Perfect Amounts'!D122+'Perfect Amounts'!D218-'Perfect Amounts'!E22-'Future Treasures'!C21<0,0,'Perfect Amounts'!D122+'Perfect Amounts'!D218-'Perfect Amounts'!E22-'Future Treasures'!C21-N5) -> 16 | M5: Wing Edge
A6: ='Perfect Amounts'!D137-'Perfect Amounts'!E137-'Buying and Synthing'!F6 -> 7 | B6: Headgear | C6: 330 | D6: =C6/2 -> 165 | E6: =IF(A6>0,C6*A6,D6*A6) -> 2310 | L6: =IF('Perfect Amounts'!D122+'Perfect Amounts'!D218+'Perfect Amounts'!D217-'Perfect Amounts'!E16-'Future Treasures'!C15<0,0,'Perfect Amounts'!D122+'Perfect Amounts'!D218+'Perfect Amounts'!D217-'Perfect Amounts'!E16-'Future Treasures'!C15-N6) -> 25 | M6: Phoenix Pinion
A7: ='Perfect Amounts'!D138-'Perfect Amounts'!E138+'Perfect Amounts'!D78-'Perfect Amounts'!E78+'Perfect Amounts'!D238-'Perfect Amounts'!E238-'Future Treasures'!C98-'Future Treasures'!C175-'Buying and Synthing'!F7 -> 14 | B7: Magus Hat | C7: 400 | D7: =C7/2 -> 200 | E7: =IF(A7>0,C7*A7,D7*A7) -> 5600 | L7: =IF('Perfect Amounts'!D226+'Perfect Amounts'!D220-'Perfect Amounts'!E251-'Future Treasures'!C203<0,0,'Perfect Amounts'!D226+'Perfect Amounts'!D220-'Perfect Amounts'!E251-'Future Treasures'!C203-N7) -> 14 | M7: Peridot
A8: ='Perfect Amounts'!D173-'Perfect Amounts'!E173-'Future Treasures'!C109-'Buying and Synthing'!F8 -> 7 | B8: Bronze Vest | C8: 670 | D8: =C8/2 -> 335 | E8: =IF(A8>0,C8*A8,D8*A8) -> 4690
A9: ='Perfect Amounts'!D226-'Perfect Amounts'!E226+'Perfect Amounts'!D220-'Perfect Amounts'!E220+'Perfect Amounts'!D234-'Perfect Amounts'!E234+'Perfect Amounts'!D199-'Perfect Amounts'!E199-'Future Treasures'!C150-'Future Treasures'!C159-'Buying and Synthing'!F9 -> 26 | B9: Linen Cuirass | C9: 800 | D9: =C9/2 -> 400 | E9: =IF(A9>0,C9*A9,D9*A9) -> 20800 | L9: Missable List
A11: TOTAL: | B11: =SUM(E5:E9) -> 39120 | L11: =-('Perfect Amounts'!D19-'Perfect Amounts'!E19-'Future Treasures'!C18) -> -3 | M11: Dark Matter
A12: Alexandria | L12: =-('Perfect Amounts'!D28-'Perfect Amounts'!E28+'Perfect Amounts'!D35-'Perfect Amounts'!E35+'Perfect Amounts'!D36-'Perfect Amounts'!E36+'Perfect Amounts'!D119-'Perfect Amounts'!E119-'Future Treasures'!C84) -> -9 | M12: Zorlin Shape
L13: =-('Perfect Amounts'!D41-'Perfect Amounts'!E41+'Perfect Amounts'!D212-'Perfect Amounts'!E212) -> -5 | M13: Mythril Sword
A14: Buy | B14: Item | C14: Cost | D14: Sell | E14: Total | F14: Amount Purchased | L14: =-('Perfect Amounts'!D42-'Future Treasures'!C32) -> -2 | M14: Blood Sword
A15: ='Perfect Amounts'!D26-'Perfect Amounts'!E26+'Perfect Amounts'!D34-'Perfect Amounts'!E34+'Perfect Amounts'!D33*2-'Perfect Amounts'!E33*2+'Perfect Amounts'!D32-'Perfect Amounts'!E32-'Buying and Synthing'!F15 -> 10 | B15: Mythril Dagger | C15: 950 | D15: =C15/2 -> 475 | E15: =IF(A15>0,C15*A15,D15*A15) -> 9500 | L15: =-('Perfect Amounts'!D45-'Perfect Amounts'!E45) -> -2 | M15: Diamond Sword
A16: ='Perfect Amounts'!D27-'Perfect Amounts'!E27+'Perfect Amounts'!D34-'Perfect Amounts'!E34+'Perfect Amounts'!D35-'Perfect Amounts'!E35+'Perfect Amounts'!D119-'Perfect Amounts'!E119-'Buying and Synthing'!F16 -> 9 | B16: Gladius | C16: 2300 | D16: =C16/2 -> 1150 | E16: =IF(A16>0,C16*A16,D16*A16) -> 20700 | L16: =-('Perfect Amounts'!D46-'Perfect Amounts'!E46) -> -2 | M16: Flame Saber
A17: ='Perfect Amounts'!D43-'Perfect Amounts'!E43-'Buying and Synthing'!F17 -> 2 | B17: Ice Brand | C17: 3780 | D17: =C17/2 -> 1890 | E17: =IF(A17>0,C17*A17,D17*A17) -> 7560 | L17: =-('Perfect Amounts'!D47-'Perfect Amounts'!E47) -> -2 | M17: Rune Blade
A18: ='Perfect Amounts'!D56-'Perfect Amounts'!E56-F18 -> 2 | B18: Partisan | C18: 1600 | D18: =C18/2 -> 800 | E18: =IF(A18>0,C18*A18,D18*A18) -> 3200 | L18: =-('Perfect Amounts'!D54-'Perfect Amounts'!E54+'Perfect Amounts'!D49-'Perfect Amounts'!E49-'Future Treasures'!C38) -> -3 | M18: Javelin
A19: ='Perfect Amounts'!D57-'Perfect Amounts'!E57-F19 -> 2 | B19: Ice Lance | C19: 2430 | D19: =C19/2 -> 1215 | E19: =IF(A19>0,C19*A19,D19*A19) -> 4860 | L19: =-('Perfect Amounts'!D58-'Perfect Amounts'!E58) -> -2 | M19: Trident
A20: ='Perfect Amounts'!D64-'Perfect Amounts'!E64-'Future Treasures'!C44-F20 -> 2 | B20: Cat's Claws | C20: 4000 | D20: =C20/2 -> 2000 | E20: =IF(A20>0,C20*A20,D20*A20) -> 8000 | L20: =-('Perfect Amounts'!D59-'Perfect Amounts'!E59) -> -2 | M20: Heavy Lance
A21: ='Perfect Amounts'!D65-'Perfect Amounts'!E65-F21 -> 2 | B21: Poison Knuckles | C21: 5000 | D21: =C21/2 -> 2500 | E21: =IF(A21>0,C21*A21,D21*A21) -> 10000 | L21: =-('Perfect Amounts'!D60-'Perfect Amounts'!E60) -> -2 | M21: Obelisk
A22: ='Perfect Amounts'!D82-'Perfect Amounts'!E82+'Perfect Amounts'!D156-'Perfect Amounts'!E156+'Perfect Amounts'!D224-'Perfect Amounts'!E224+'Perfect Amounts'!D225-'Perfect Amounts'!E225+'Perfect Amounts'!D226-'Perfect Amounts'!E226-'Future Treasures'!C154-'Future Treasures'!C156-'Future Treasures'!C159-'Future Treasures'!C102-F22 -> 36 | B22: Stardust Rod | C22: 760 | D22: =C22/2 -> 380 | E22: =IF(A22>0,C22*A22,D22*A22) -> 27360 | L22: =-('Perfect Amounts'!D66-'Perfect Amounts'!E66) -> -2 | M22: Mythril Claws
A23: ='Perfect Amounts'!D83-'Perfect Amounts'!E83-F23 -> 2 | B23: Healing Rod | C23: 1770 | D23: =C23/2 -> 885 | E23: =IF(A23>0,C23*A23,D23*A23) -> 3540 | L23: =-('Perfect Amounts'!D67-'Perfect Amounts'!E67) -> -2 | M23: Scissor Fangs
A24: ='Perfect Amounts'!D88-'Perfect Amounts'!E88-F24 -> 2 | B24: Lamia's Flute | C24: 3800 | D24: =C24/2 -> 1900 | E24: =IF(A24>0,C24*A24,D24*A24) -> 7600 | L24: =-('Perfect Amounts'!D69-'Perfect Amounts'!E69) -> -2 | M24: Tiger Fangs
A25: ='Perfect Amounts'!D94-'Perfect Amounts'!E94-F25 -> 2 | B25: Flame Staff | C25: 1100 | D25: =C25/2 -> 550 | E25: =IF(A25>0,C25*A25,D25*A25) -> 2200 | L25: =-('Perfect Amounts'!D74-'Perfect Amounts'!E74+'Perfect Amounts'!D78-'Perfect Amounts'!E78-'Future Treasures'!C54) -> -6 | M25: Air Racket
A26: ='Perfect Amounts'!D95-'Perfect Amounts'!E95-F26 -> 2 | B26: Ice Staff | C26: 980 | D26: =C26/2 -> 490 | E26: =IF(A26>0,C26*A26,D26*A26) -> 1960 | L26: =-('Perfect Amounts'!D84-'Perfect Amounts'!E84) -> -2 | M26: Asura's Rod
A27: ='Perfect Amounts'!D96-'Perfect Amounts'!E96+'Perfect Amounts'!D227-'Perfect Amounts'!E227-F27 -> 11 | B27: Lightning Staff | C27: 1200 | D27: =C27/2 -> 600 | E27: =IF(A27>0,C27*A27,D27*A27) -> 13200 | L27: =-('Perfect Amounts'!D89-'Perfect Amounts'!E89) -> -2 | M27: Fairy Flute
A28: ='Perfect Amounts'!D97-'Perfect Amounts'!E97-F28 -> 2 | B28: Oak Staff | C28: 2400 | D28: =C28/2 -> 1200 | E28: =IF(A28>0,C28*A28,D28*A28) -> 4800 | L28: =-('Perfect Amounts'!D90-'Perfect Amounts'!E90) -> -2 | M28: Hamelin
A29: ='Perfect Amounts'!D20-'Perfect Amounts'!E20-F29 -> 99 | B29: Pinwheel | C29: 200 | D29: =C29/2 -> 100 | E29: =IF(A29>0,C29*A29,D29*A29) -> 19800 | L29: =-('Perfect Amounts'!D99-'Perfect Amounts'!E99) -> -2 | M29: Octogon Rod
A30: ='Perfect Amounts'!D111-'Perfect Amounts'!E111+'Perfect Amounts'!D168-'Perfect Amounts'!E168+'Perfect Amounts'!D195-'Perfect Amounts'!E195+'Perfect Amounts'!D221-'Perfect Amounts'!E221+'Perfect Amounts'!D223-'Perfect Amounts'!E223-'Future Treasures'!C129-F30 -> 33 | B30: Glass Armlet | C30: 250 | D30: =C30/2 -> 125 | E30: =IF(A30>0,C30*A30,D30*A30) -> 8250 | L30: =-('Perfect Amounts'!D105-'Perfect Amounts'!E105-'Future Treasures'!C72) -> -2 | M30: Silver Fork
A31: ='Perfect Amounts'!D112-'Perfect Amounts'!E112+'Perfect Amounts'!D122-'Perfect Amounts'!E122+'Perfect Amounts'!D156-'Perfect Amounts'!E156+'Perfect Amounts'!D214-'Perfect Amounts'!E214+'Perfect Amounts'!D217-'Perfect Amounts'!E217+'Perfect Amounts'!D218-'Perfect Amounts'!E218+'Perfect Amounts'!D224-'Perfect Amounts'!E224+'Perfect Amounts'!D225-'Perfect Amounts'!E225+'Perfect Amounts'!D226-'Perfect Amounts'!E226-'Future Treasures'!C102-'Future Treasures'!C144-'Future Treasures'!C146-'Future Treasures'!C154-'Future Treasures'!C156-'Future Treasures'!C159-F31 -> 75 | B31: Bone Wrist | C31: 330 | D31: =C31/2 -> 165 | E31: =IF(A31>0,C31*A31,D31*A31) -> 24750 | L31: =-('Perfect Amounts'!D124-'Perfect Amounts'!E124+'Perfect Amounts'!D49-'Perfect Amounts'!E49-'Future Treasures'!C86) -> -4 | M31: Silver Gloves
A32: ='Perfect Amounts'!D113-'Perfect Amounts'!E113+'Perfect Amounts'!D119-'Perfect Amounts'!E119-F32 -> 10 | B32: Mythril Armlet | C32: 500 | D32: =C32/2 -> 250 | E32: =IF(A32>0,C32*A32,D32*A32) -> 5000 | L32: =-('Perfect Amounts'!D127-'Perfect Amounts'!E127-'Future Treasures'!C90) -> -3 | M32: Diamond Gloves
A33: ='Perfect Amounts'!D114-'Perfect Amounts'!E114+'Perfect Amounts'!D235-'Perfect Amounts'!E235+'Perfect Amounts'!D236-'Perfect Amounts'!E236-F33 -> 18 | B33: Magic Armlet | C33: 1000 | D33: =C33/2 -> 500 | E33: =IF(A33>0,C33*A33,D33*A33) -> 18000 | L33: =-('Perfect Amounts'!D130-'Perfect Amounts'!E130-'Future Treasures'!C92) -> -2 | M33: Genji Gloves
A34: ='Perfect Amounts'!D125-'Perfect Amounts'!E125+'Perfect Amounts'!D132-'Perfect Amounts'!E132-'Future Treasures'!C88-F34 -> 6 | B34: Mythril Gloves | C34: 980 | D34: =C34/2 -> 490 | E34: =IF(A34>0,C34*A34,D34*A34) -> 5880 | L34: =-('Perfect Amounts'!D139-'Perfect Amounts'!E139+'Perfect Amounts'!D190-'Perfect Amounts'!E190-'Future Treasures'!C119) -> -12 | M34: Bandana
A35: ='Perfect Amounts'!D126-'Perfect Amounts'!E126-F35 -> 3 | B35: Thunder Gloves | C35: 1200 | D35: =C35/2 -> 600 | E35: =IF(A35>0,C35*A35,D35*A35) -> 3600 | L35: =-('Perfect Amounts'!D146-'Perfect Amounts'!E146) -> -7 | M35: Green Beret
A36: ='Perfect Amounts'!D141-'Perfect Amounts'!E141+'Perfect Amounts'!D240-'Perfect Amounts'!E240-F36 -> 9 | B36: Lamia's Tiara | C36: 800 | D36: =C36/2 -> 400 | E36: =IF(A36>0,C36*A36,D36*A36) -> 7200 | L36: =-('Perfect Amounts'!D147-'Perfect Amounts'!E147) -> -6 | M36: Black Hood
A37: ='Perfect Amounts'!D142-'Perfect Amounts'!E142-F37 -> 7 | B37: Ritual Hat | C37: 1000 | D37: =C37/2 -> 500 | E37: =IF(A37>0,C37*A37,D37*A37) -> 7000 | L37: =-('Perfect Amounts'!D159-'Perfect Amounts'!E159) -> -3 | M37: Iron Helm
A38: ='Perfect Amounts'!D143-'Perfect Amounts'!E143+'Perfect Amounts'!D222-'Perfect Amounts'!E222-'Future Treasures'!C152-F38 -> 16 | B38: Twist Headband | C38: 1200 | D38: =C38/2 -> 600 | E38: =IF(A38>0,C38*A38,D38*A38) -> 19200 | L38: =-('Perfect Amounts'!D167-'Perfect Amounts'!E167-'Future Treasures'!C104) -> -2 | M38: Genji Helmet
A39: ='Perfect Amounts'!D239-'Perfect Amounts'!E239+'Perfect Amounts'!D236-'Perfect Amounts'!E236+'Perfect Amounts'!D160-'Perfect Amounts'!E160-'Future Treasures'!C177-F39 -> 11 | B39: Barbut | C39: 600 | D39: =C39/2 -> 300 | E39: =IF(A39>0,C39*A39,D39*A39) -> 6600 | L39: =-('Perfect Amounts'!D172-'Perfect Amounts'!E172) -> -3 | M39: Leather Plate
A40: ='Perfect Amounts'!D161-'Perfect Amounts'!E161-F40 -> 3 | B40: Mythril Helm | C40: 1000 | D40: =C40/2 -> 500 | E40: =IF(A40>0,C40*A40,D40*A40) -> 3000 | L40: =-('Perfect Amounts'!D174-'Perfect Amounts'!E174) -> -3 | M40: Chain Plate
A41: ='Perfect Amounts'!D162-'Perfect Amounts'!E162+'Perfect Amounts'!D155-'Perfect Amounts'!E155-F41 -> 10 | B41: Gold Helm | C41: 1800 | D41: =C41/2 -> 900 | E41: =IF(A41>0,C41*A41,D41*A41) -> 18000 | L41: =-('Perfect Amounts'!D175-'Perfect Amounts'!E175+'Perfect Amounts'!D188-'Perfect Amounts'!E188) -> -10 | M41: Mythril Vest
...

Sheet Math Behind This
A1: Math Behind This
